<mujoco model="booster_t1">
  <compiler angle="radian" autolimits="true" />

  <worldbody>
    <body name="Trunk" pos="0 0 0.7">
      <inertial pos="0.055138 -1.42184e-06 0.105043" quat="0.999959 1.39867e-05 -0.00902028 -1.39205e-05" mass="11.7016" diaginertia="0.0915734 0.0768118 0.0556067" />
      <site name="imu" size="0.01" pos="0.0 0.0 0.0" />
      <joint name="world_joint" type="free" limited="false" actuatorfrclimited="false" />
      <geom name="trunk_collision" size="0.085 0.09 0.145" pos="0.06 0 0.12" type="box" contype="1" conaffinity="0" rgba="0.76 0.76 0.76 0." />
      <body name="H1" pos="0.0625 0 0.243">
        <inertial pos="-0.000508 -0.001403 0.057432" quat="0.763881 -0.0132172 0.00173419 0.645219" mass="0.44391" diaginertia="0.000241549 0.00022351 0.000149941" />
        <joint name="AAHead_yaw" pos="0 0 0" axis="0 0 1" range="-1.57 1.57" />
        <geom size="0.025 0.035" pos="0 0 0.06" quat="0.707105 0.707108 0 0" type="cylinder" rgba="0.4 0.4 0.4 0." contype="0" conaffinity="0" density="0" />
        <body name="H2" pos="0 0 0.06185">
          <inertial pos="0.007802 0.001262 0.098631" quat="0.988453 0.106172 -0.0745686 -0.0782786" mass="0.631019" diaginertia="0.00203553 0.00192467 0.00172381" />
          <joint name="Head_pitch" pos="0 0 0" axis="0 1 0" range="-0.35 1.22" />
          <geom size="0.08" pos="0.01 0 0.11" rgba="0.4 0.4 0.4 0.5" contype="0" conaffinity="0" density="0" />
        </body>
      </body>
      <body name="AL1" pos="0.0575 0.1063 0.219" quat="1 0 0.000440565 0">
        <inertial pos="-0.000677 0.044974 0" quat="0.50423 0.495734 -0.50423 0.495734" mass="0.53" diaginertia="0.001367 0.00129329 0.000292711" />
        <joint name="Left_Shoulder_Pitch" pos="0 0 0" axis="0 1 0" range="-3.31 1.22" armature="0.05" />
        <geom size="0.03 0.035" pos="0 0.047 0" quat="0.707105 0 0.707108 0" type="cylinder" rgba="0.76 0.76 0.76 0." contype="0" conaffinity="0" density="0" />
        <body name="AL2" pos="0 0.047 0">
          <inertial pos="0.003862 0.037976 0" quat="0.487991 0.511727 -0.487991 0.511727" mass="0.16" diaginertia="0.000401 0.00034538 0.00017662" />
          <joint name="Left_Shoulder_Roll" pos="0 0 0" axis="1 0 0" range="-1.74 1.57" />
          <body name="AL3" pos="0.00025 0.0605 0">
            <inertial pos="0 0.085353 -9.9e-05" quat="0.70641 0.707803 0 0" mass="1.02" diaginertia="0.012869 0.012798 0.000620953" />
            <joint name="Left_Elbow_Pitch" pos="0 0 0" axis="0 1 0" range="-2.27 2.27" armature="0.05" />
            <geom size="0.03 0.095" pos="0 0.07 0" quat="0.707105 0.707108 0 0" type="cylinder" rgba="0.4 0.4 0.4 0." contype="0" conaffinity="0" density="0" />
            <body name="left_hand_link" pos="0 0.1471 0">
              <inertial pos="-0.000107344 0.11022 0.00058741" quat="0.707869 0.706344 -5.3547e-05 -0.000214933" mass="0.329214" diaginertia="0.00819152 0.00816355 0.000224963" />
              <joint name="Left_Elbow_Yaw" pos="0 0 0" axis="0 0 1" range="-2.44 0" />
              <geom size="0.029 0.065" pos="0 0.12 0" quat="0.707105 0.707108 0 0" type="cylinder" rgba="0.4 0.4 0.4 0." contype="0" conaffinity="0" density="0" />
              <geom size="0.031" pos="0 0.216 0" contype="0" conaffinity="0" density="0" />
            </body>
          </body>
        </body>
      </body>
      <body name="AR1" pos="0.0575 -0.1063 0.219" quat="1 0 0.000440565 0">
        <inertial pos="-0.000677 -0.044974 0" quat="0.50423 0.495734 -0.50423 0.495734" mass="0.53" diaginertia="0.001367 0.00129329 0.000292711" />
        <joint name="Right_Shoulder_Pitch" pos="0 0 0" axis="0 1 0" range="-3.31 1.22" armature="0.05" />
        <geom size="0.03 0.035" pos="0 -0.047 0" quat="0.707105 0 0.707108 0" type="cylinder" rgba="0.76 0.76 0.76 0." contype="0" conaffinity="0" density="0" />
        <body name="AR2" pos="0 -0.047 0">
          <inertial pos="0.003862 -0.037976 0" quat="0.511727 0.487991 -0.511727 0.487991" mass="0.16" diaginertia="0.000401 0.00034538 0.00017662" />
          <joint name="Right_Shoulder_Roll" pos="0 0 0" axis="1 0 0" range="-1.57 1.74" />
          <body name="AR3" pos="0.00025 -0.0605 0">
            <inertial pos="0 -0.085353 -9.9e-05" quat="0.707803 0.70641 0 0" mass="1.02" diaginertia="0.012869 0.012798 0.000620953" />
            <joint name="Right_Elbow_Pitch" pos="0 0 0" axis="0 1 0" range="-2.27 2.27" armature="0.05" />
            <geom size="0.03 0.095" pos="0 -0.07 0" quat="0.707105 0.707108 0 0" type="cylinder" rgba="0.4 0.4 0.4 0." contype="0" conaffinity="0" density="0" />
            <body name="right_hand_link" pos="0 -0.1471 0">
              <inertial pos="-0.000107344 -0.11022 0.00058741" quat="0.706344 0.707869 0.000214933 5.3547e-05" mass="0.329214" diaginertia="0.00819152 0.00816355 0.000224963" />
              <joint name="Right_Elbow_Yaw" pos="0 0 0" axis="0 0 1" range="0 2.44" />
              <geom size="0.029 0.065" pos="0 -0.12 0" quat="0.707105 0.707108 0 0" type="cylinder" rgba="0.4 0.4 0.4 0." contype="0" conaffinity="0" density="0" />
              <geom size="0.031" pos="0 -0.216 0" contype="0" conaffinity="0" density="0" />
            </body>
          </body>
        </body>
      </body>
      <body name="Waist" pos="0.0625 0 -0.1155">
        <inertial pos="0.002284 3e-06 0.007301" quat="0.983649 0.000360386 -0.180076 0.00269791" mass="2.581" diaginertia="0.00536742 0.005299 0.00474258" />
        <joint name="Waist" pos="0 0 0" axis="0 0 1" range="-1.57 1.57" />
        <geom size="0.06 0.05" quat="0.707105 0.707108 0 0" type="cylinder" rgba="0.4 0.4 0.4 0." contype="0" conaffinity="0" density="0" />
        <body name="Hip_Pitch_Left" pos="0 0.106 0">
          <inertial pos="0.000534 -0.007296 -0.018083" quat="0.975141 0.2211 0.0145808 0.0017406" mass="1.021" diaginertia="0.00180547 0.00145926 0.00125327" />
          <joint name="Left_Hip_Pitch" pos="0 0 0" axis="0 1 0" range="-3.002 2.2166" />
          <geom size="0.045 0.0425" pos="-0.002 0 -0.02" quat="0.707105 0 0.707108 0" type="cylinder" rgba="0.76 0.76 0.76 0." contype="0" conaffinity="0" density="0" />
          <body name="Hip_Roll_Left" pos="0 0 -0.02">
            <inertial pos="0.001101 2.4e-05 -0.05375" quat="0.707081 -0.00599604 -0.00599604 0.707081" mass="0.385" diaginertia="0.001743 0.00151729 0.000514712" />
            <joint name="Left_Hip_Roll" pos="0 0 0" axis="1 0 0" range="-0.2 1.57" />
            <body name="Hip_Yaw_Left" pos="0 0 -0.081854">
              <inertial pos="-0.007233 0.000206 -0.089184" quat="0.696808 -0.033953 -0.0315708 0.715758" mass="2.166" diaginertia="0.0257334 0.0253024 0.00259215" />
              <joint name="Left_Hip_Yaw" pos="0 0 0" axis="0 0 1" range="-1 1" />
              <geom size="0.055 0.045" pos="-0.015 0 -0.135" quat="0.707105 0.707108 0 0" type="cylinder" rgba="0.4 0.4 0.4 0." contype="0" conaffinity="0" density="0" />
              <body name="Shank_Left" pos="-0.014 0 -0.134">
                <inertial pos="-0.006012 0.000259 -0.124318" quat="0.997573 0.00144024 -0.023949 0.0653706" mass="1.82" diaginertia="0.0346951 0.0345375 0.00185844" />
                <joint name="Left_Knee_Pitch" pos="0 0 0" axis="0 1 0" range="0 2.1817" />
                <geom size="0.05 0.04 0.07" pos="0 0 -0.15" type="box" rgba="0.4 0.4 0.4 0." contype="0" conaffinity="0" density="0" />
                <body name="Ankle_Cross_Left" pos="0 0 -0.28">
                  <inertial pos="-0.003722 0 -0.007981" quat="0.443136 0.551027 0.551027 0.443136" mass="0.073" diaginertia="2.9e-05 2.56589e-05 1.13411e-05" />
                  <joint name="Left_Ankle_Pitch" pos="0 0 0" axis="0 1 0" range="-0.87 0.35" armature="0.05" />
                  <body name="left_foot_link" pos="0 0.00025 -0.012">
                    <inertial pos="-0.000249 0 -0.00914" quat="0 0.651138 0 0.75896" mass="0.685" diaginertia="0.00269361 0.002385 0.00171539" />
                    <joint name="Left_Ankle_Roll" pos="0 0 0" axis="1 0 0" range="-0.44 0.44" armature="0.05" />
                    <geom name="l_foot_collision" size="0.112434 0.05 0.02183" pos="0.0101079 0 -0.0214208" type="box" contype="1" conaffinity="0" rgba="0.4 0.4 0.4 0." />
                  </body>
                </body>
              </body>
            </body>
          </body>
        </body>
        <body name="Hip_Pitch_Right" pos="0 -0.106 0">
          <inertial pos="0.000534 0.007514 -0.018082" quat="0.973446 -0.228403 0.0147148 -0.00419349" mass="1.021" diaginertia="0.00180552 0.0014632 0.00124928" />
          <joint name="Right_Hip_Pitch" pos="0 0 0" axis="0 1 0" range="-3.002 2.2166" />
          <geom size="0.045 0.0425" pos="-0.002 0 -0.02" quat="0.707105 0 0.707108 0" type="cylinder" rgba="0.76 0.76 0.76 0." contype="0" conaffinity="0" density="0" />
          <body name="Hip_Roll_Right" pos="0 0 -0.02">
            <inertial pos="0.001099 2.4e-05 -0.053748" quat="0.707081 -0.00599604 -0.00599604 0.707081" mass="0.385" diaginertia="0.001743 0.00151729 0.000514712" />
            <joint name="Right_Hip_Roll" pos="0 0 0" axis="1 0 0" range="-1.57 0.2" />
            <body name="Hip_Yaw_Right" pos="0 0 -0.081854">
              <inertial pos="-0.007191 -0.000149 -0.08922" quat="0.714468 -0.0315638 -0.0336391 0.698146" mass="2.17" diaginertia="0.0257623 0.0253298 0.00259389" />
              <joint name="Right_Hip_Yaw" pos="0 0 0" axis="0 0 1" range="-1 1" />
              <geom size="0.055 0.045" pos="-0.015 0 -0.135" quat="0.707105 0.707108 0 0" type="cylinder" rgba="0.4 0.4 0.4 0." contype="0" conaffinity="0" density="0" />
              <body name="Shank_Right" pos="-0.014 0 -0.134">
                <inertial pos="-0.005741 -0.000541 -0.122602" quat="0.99926 -0.000580963 -0.023461 -0.0304754" mass="1.82" diaginertia="0.0351717 0.0349574 0.00196589" />
                <joint name="Right_Knee_Pitch" pos="0 0 0" axis="0 1 0" range="0 2.1817" />
                <geom size="0.05 0.04 0.07" pos="0 0 -0.15" type="box" rgba="0.4 0.4 0.4 0." contype="0" conaffinity="0" density="0" />
                <body name="Ankle_Cross_Right" pos="0 0 -0.28">
                  <inertial pos="-0.003722 0 -0.007981" quat="0.443136 0.551027 0.551027 0.443136" mass="0.073" diaginertia="2.9e-05 2.56589e-05 1.13411e-05" />
                  <joint name="Right_Ankle_Pitch" pos="0 0 0" axis="0 1 0" range="-0.87 0.35" armature="0.05" />
                  <body name="right_foot_link" pos="0 -0.00025 -0.012">
                    <inertial pos="-0.000248 0 -0.00914" quat="0 0.651138 0 0.75896" mass="0.685" diaginertia="0.00269361 0.002385 0.00171539" />
                    <joint name="Right_Ankle_Roll" pos="0 0 0" axis="1 0 0" range="-0.44 0.44" armature="0.05" />
                    <geom name="r_foot_collision" size="0.112434 0.05 0.02183" pos="0.0101079 0 -0.0214208" type="box" contype="1" conaffinity="0" rgba="0.4 0.4 0.4 0." />
                  </body>
                </body>
              </body>
            </body>
          </body>
        </body>
      </body>
    </body>
  </worldbody>

  <sensor>
    <framequat name="orientation" objtype="site" noise="0.001" objname="imu" />
    <gyro name="angular-velocity" site="imu" noise="0.005" />
  </sensor>
</mujoco>